Workbook

Sheet Team List
A1: Team | B1: Seed | C1: Region | D1: Opponent | E1: Opponent Seed | F1: Team_2 | G1: Seed_2 | H1: Region_2 | I1: Opponent_2 | J1: Opponent Seed_2
A2: Duke | B2: 1 | C2: East | D2: Siena | E2: =INDEX($B$2:$B$65, MATCH(D2, $A$2:$A$65, 0)) -> 16 | F2: Duke | G2: 1 | H2: East | I2: Siena | J2: 16
A3: Siena | B3: 16 | C3: East | D3: Duke | E3: =INDEX($B$2:$B$65, MATCH(D3, $A$2:$A$65, 0)) -> 1 | F3: Michigan | G3: 1 | H3: Midwest | I3: Howard | J3: 16
A4: Ohio St. | B4: 8 | C4: East | D4: TCU | E4: =INDEX($B$2:$B$65, MATCH(D4, $A$2:$A$65, 0)) -> 9 | F4: Florida | G4: 1 | H4: South | I4: Prairie View A&M | J4: 16
A5: TCU | B5: 9 | C5: East | D5: Ohio St. | E5: =INDEX($B$2:$B$65, MATCH(D5, $A$2:$A$65, 0)) -> 8 | F5: Arizona | G5: 1 | H5: West | I5: LIU | J5: 16
A6: St. John's | B6: 5 | C6: East | D6: Northern Iowa | E6: =INDEX($B$2:$B$65, MATCH(D6, $A$2:$A$65, 0)) -> 12 | F6: Connecticut | G6: 2 | H6: East | I6: Furman | J6: 15
A7: Northern Iowa | B7: 12 | C7: East | D7: St. John's | E7: =INDEX($B$2:$B$65, MATCH(D7, $A$2:$A$65, 0)) -> 5 | F7: Iowa St. | G7: 2 | H7: Midwest | I7: Tennessee St. | J7: 15
A8: Kansas | B8: 4 | C8: East | D8: Cal Baptist | E8: =INDEX($B$2:$B$65, MATCH(D8, $A$2:$A$65, 0)) -> 13 | F8: Houston | G8: 2 | H8: South | I8: Idaho | J8: 15
A9: Cal Baptist | B9: 13 | C9: East | D9: Kansas | E9: =INDEX($B$2:$B$65, MATCH(D9, $A$2:$A$65, 0)) -> 4 | F9: Purdue | G9: 2 | H9: West | I9: Queens | J9: 15
A10: Louisville | B10: 6 | C10: East | D10: South Florida | E10: =INDEX($B$2:$B$65, MATCH(D10, $A$2:$A$65, 0)) -> 11 | F10: Michigan St. | G10: 3 | H10: East | I10: North Dakota St. | J10: 14
A11: South Florida | B11: 11 | C11: East | D11: Louisville | E11: =INDEX($B$2:$B$65, MATCH(D11, $A$2:$A$65, 0)) -> 6 | F11: Virginia | G11: 3 | H11: Midwest | I11: Wright St. | J11: 14
A12: Michigan St. | B12: 3 | C12: East | D12: North Dakota St. | E12: =INDEX($B$2:$B$65, MATCH(D12, $A$2:$A$65, 0)) -> 14 | F12: Illinois | G12: 3 | H12: South | I12: Penn | J12: 14
A13: North Dakota St. | B13: 14 | C13: East | D13: Michigan St. | E13: =INDEX($B$2:$B$65, MATCH(D13, $A$2:$A$65, 0)) -> 3 | F13: Gonzaga | G13: 3 | H13: West | I13: Kennesaw St. | J13: 14
... A65: Tennessee St. | B65: 15 | C65: Midwest | D65: Iowa St. | E65: =INDEX($B$2:$B$65, MATCH(D65, $A$2:$A$65, 0)) -> 2 | F65: LIU | G65: 16 | H65: West | I65: Arizona | J65: 1

Sheet Bart Torvik
A1: Rk | B1: Team | C1: Barthag | D1: AdjOE | E1: AdjDE | F1: Net Rating (AdjOE-AdjDE) | G1: EFG% | H1: EFGD% | I1: TOR | J1: TORD | K1: ORB | L1: DRB | M1: FTR | N1: 3P % | O1: 3P %D
A2: 1 | B2: Duke | C2: 0.9813 | D2: 128.2 | E2: 90.8 | F2: =D2-E2 -> 37.4 | G2: 56.8 | H2: 46.2 | I2: 15.7 | J2: 18.1 | K2: 38.1 | L2: 24.8 | M2: 37.8 | N2: 35.1 | O2: 30.4
A3: 2 | B3: Michigan | C3: 0.9799 | D3: 127.7 | E3: 91 | F3: =D3-E3 -> 36.7 | G3: 58.1 | H3: 44.7 | I3: 16.7 | J3: 15.5 | K3: 35.4 | L3: 27.7 | M3: 37.7 | N3: 36 | O3: 30.2
A4: 3 | B4: Arizona | C4: 0.9776 | D4: 126.9 | E4: 91.4 | F4: =D4-E4 -> 35.5 | G4: 55.1 | H4: 45 | I4: 15.1 | J4: 16.7 | K4: 38.1 | L4: 26.9 | M4: 42.9 | N4: 36 | O4: 31.4
A5: 4 | B5: Florida | C5: 0.9732 | D5: 126.1 | E5: 92.3 | F5: =D5-E5 -> 33.8 | G5: 53.5 | H5: 46.3 | I5: 16.5 | J5: 15.4 | K5: 43.2 | L5: 24.8 | M5: 39.1 | N5: 30.8 | O5: 32.4
A6: 5 | B6: Houston | C6: 0.9709 | D6: 125.3 | E6: 92.4 | F6: =D6-E6 -> 32.9 | G6: 52.1 | H6: 46.6 | I6: 13 | J6: 21 | K6: 35.9 | L6: 30.9 | M6: 26.9 | N6: 34.9 | O6: 32.1
A7: 6 | B7: Illinois | C7: 0.9676 | D7: 131.9 | E7: 98.2 | F7: =D7-E7 -> 33.7 | G7: 55.1 | H7: 47.6 | I7: 13.2 | J7: 11.6 | K7: 38.7 | L7: 27 | M7: 32.9 | N7: 34.7 | O7: 31.4
A8: 7 | B8: Iowa St. | C8: 0.9655 | D8: 123.8 | E8: 92.6 | F8: =D8-E8 -> 31.2 | G8: 56.5 | H8: 49.5 | I8: 15.1 | J8: 22.4 | K8: 35.3 | L8: 28.1 | M8: 34 | N8: 38.7 | O8: 32.1
A9: 8 | B9: Purdue | C9: 0.9636 | D9: 133.3 | E9: 100.3 | F9: =D9-E9 -> 33 | G9: 57.6 | H9: 52.3 | I9: 13.5 | J9: 15.6 | K9: 36.3 | L9: 26.4 | M9: 28.6 | N9: 37.9 | O9: 34.2
A10: 9 | B10: Connecticut | C10: 0.9517 | D10: 123.1 | E10: 95 | F10: =D10-E10 -> 28.1 | G10: 55.3 | H10: 45.7 | I10: 16.8 | J10: 18 | K10: 35.7 | L10: 28.7 | M10: 30 | N10: 35.2 | O10: 30.3
A11: 10 | B11: Vanderbilt | C11: 0.9461 | D11: 127.5 | E11: 99.4 | F11: =D11-E11 -> 28.1 | G11: 55.3 | H11: 48.8 | I11: 13.3 | J11: 17.9 | K11: 31.2 | L11: 31.6 | M11: 38.2 | N11: 35.5 | O11: 32.2
A12: 11 | B12: Gonzaga | C12: 0.9446 | D12: 120.3 | E12: 94 | F12: =D12-E12 -> 26.3 | G12: 56.3 | H12: 46.2 | I12: 13.7 | J12: 20.5 | K12: 34.8 | L12: 25.9 | M12: 31.1 | N12: 34 | O12: 30.8
A13: 12 | B13: Texas Tech | C13: 0.9439 | D13: 126.3 | E13: 98.8 | F13: =D13-E13 -> 27.5 | G13: 56.2 | H13: 49.4 | I13: 15.9 | J13: 14.7 | K13: 33.3 | L13: 30.1 | M13: 27.1 | N13: 39.3 | O13: 31.5
... A69: 283 | B69: Lehigh | C69: 0.2517 | D69: 102.6 | E69: 112.8 | F69: =D69-E69 -> -10.2 | G69: 53.3 | H69: 50.6 | I69: 17.5 | J69: 16.3 | K69: 22.8 | L69: 31.7 | M69: 32.2 | N69: 36.5 | O69: 32.8

Sheet Team Ratings
A1: Team | B1: Seed | C1: Region | D1: Barthag | E1: AdjOE | F1: AdjDE | G1: Net Rating | H1: EFG% | I1: EFGD% | J1: TOR | K1: TORD | L1: ORB | M1: DRB | N1: FTR | O1: 3P% | P1: 3P%D | Q1: Injury Impact Score | R1: AdjOE (recent) | S1: AdjDE (recent) | T1: Net Rating (recent) | U1: Metric Source
A2: Duke | B2: 1 | C2: East | D2: 0.9813 | E2: 128.2 | F2: 90.8 | G2: 37.4 | H2: 56.8 | I2: 46.2 | J2: 15.7 | K2: 18.1 | L2: 38.1 | M2: 24.8 | N2: 37.8 | O2: 35.1 | P2: 30.4 | Q2: -2.5 | R2: 132.2 | S2: 94.1 | T2: 38.1 | U2: Bart Torvik + Torvik Recent
A3: Connecticut | B3: 2 | C3: East | D3: 0.9517 | E3: 123.1 | F3: 95 | G3: 28.1 | H3: 55.3 | I3: 45.7 | J3: 16.8 | K3: 18 | L3: 35.7 | M3: 28.7 | N3: 30 | O3: 35.2 | P3: 30.3 | Q3: 0 | R3: 114.9 | S3: 95.4 | T3: 19.5 | U3: Bart Torvik + Torvik Recent
A4: Michigan St. | B4: 3 | C4: East | D4: 0.9438 | E4: 122.9 | F4: 96.2 | G4: 26.7 | H4: 53.6 | I4: 48.6 | J4: 17.1 | K4: 14.8 | L4: 38.5 | M4: 22.6 | N4: 36.2 | O4: 35.9 | P4: 32.9 | Q4: 0 | R4: 135 | S4: 108.6 | T4: 26.4 | U4: Bart Torvik + Torvik Recent
A5: Kansas | B5: 4 | C5: East | D5: 0.9278 | E5: 117.8 | F5: 94.4 | G5: 23.4 | H5: 51.6 | I5: 45.2 | J5: 15.5 | K5: 14 | L5: 29.5 | M5: 30.1 | N5: 32.6 | O5: 35 | P5: 30.7 | Q5: 0 | R5: 107.4 | S5: 98.7 | T5: 8.7 | U5: Bart Torvik + Torvik Recent
A6: St. John's | B6: 5 | C6: East | D6: 0.9415 | E6: 119.8 | F6: 94.1 | G6: 25.7 | H6: 51 | I6: 47.4 | J6: 14.7 | K6: 19.4 | L6: 35.9 | M6: 30.2 | N6: 41.9 | O6: 33.2 | P6: 31.3 | Q6: 0 | R6: 123.3 | S6: 91.1 | T6: 32.2 | U6: Bart Torvik + Torvik Recent
A7: Louisville | B7: 6 | C7: East | D7: 0.9364 | E7: 124 | F7: 98.2 | G7: 25.8 | H7: 56.4 | I7: 48.8 | J7: 16.4 | K7: 16.7 | L7: 32.9 | M7: 26.9 | N7: 33.5 | O7: 35.7 | P7: 32.7 | Q7: -2.5 | R7: 124.2 | S7: 98.2 | T7: 26 | U7: Bart Torvik + Torvik Recent
A8: UCLA | B8: 7 | C8: East | D8: 0.9107 | E8: 124.6 | F8: 101.8 | G8: 22.8 | H8: 53.9 | I8: 50.4 | J8: 13.4 | K8: 18.1 | L8: 31.1 | M8: 32.4 | N8: 33.1 | O8: 38.2 | P8: 31.8 | Q8: -1 | R8: 133.4 | S8: 96.4 | T8: 37 | U8: Bart Torvik + Torvik Recent
A9: Ohio St. | B9: 8 | C9: East | D9: 0.9172 | E9: 125.2 | F9: 101.6 | G9: 23.6 | H9: 56.5 | I9: 50.3 | J9: 15.4 | K9: 15.8 | L9: 30.8 | M9: 30 | N9: 37.8 | O9: 36 | P9: 31.6 | Q9: 0 | R9: 136.6 | S9: 98.2 | T9: 38.4 | U9: Bart Torvik + Torvik Recent
A10: TCU | B10: 9 | C10: East | D10: 0.8367 | E10: 114.9 | F10: 99.6 | G10: 15.3 | H10: 50.9 | I10: 51 | J10: 15.5 | K10: 19.7 | L10: 34.4 | M10: 29.2 | N10: 38.7 | O10: 33.1 | P10: 33.7 | Q10: 0 | R10: 126.6 | S10: 101 | T10: 25.6 | U10: Bart Torvik + Torvik Recent
A11: UCF | B11: 10 | C11: East | D11: 0.8116 | E11: 120 | F11: 105.7 | G11: 14.3 | H11: 52.8 | I11: 52.4 | J11: 15.7 | K11: 15.8 | L11: 34.4 | M11: 28.5 | N11: 30.8 | O11: 36.2 | P11: 34 | Q11: -0.5 | R11: 107.1 | S11: 104.4 | T11: 2.7 | U11: Bart Torvik + Torvik Recent
A12: South Florida | B12: 11 | C12: East | D12: 0.8356 | E12: 116.8 | F12: 101.4 | G12: 15.4 | H12: 50.9 | I12: 48.4 | J12: 15.2 | K12: 18.8 | L12: 38.2 | M12: 31.8 | N12: 41.1 | O12: 33.1 | P12: 33.9 | Q12: 0 | R12: 116.9 | S12: 95.3 | T12: 21.6 | U12: Bart Torvik + Torvik Recent
A13: Northern Iowa | B13: 12 | C13: East | D13: 0.7752 | E13: 109.8 | F13: 98.6 | G13: 11.2 | H13: 54.2 | I13: 47.2 | J13: 14.6 | K13: 18.1 | L13: 22 | M13: 26.3 | N13: 25.7 | O13: 34.9 | P13: 28.9 | Q13: 0 | R13: 120.9 | S13: 99 | T13: 21.9 | U13: Bart Torvik + Torvik Recent
... A73: UMBC | B73: 16 | C73: Midwest | D73: 0.4563 | E73: 107.6 | F73: 109.2 | G73: -1.6 | H73: 53.9 | I73: 49.2 | J73: 14.1 | K73: 15.2 | L73: 25.1 | M73: 25.6 | N73: 33.8 | O73: 35.9 | P73: 32.2 | Q73: 0 | R73: 117.6 | S73: 105.8 | T73: 11.8 | U73: Bart Torvik + Torvik Recent

Sheet Team Metrics
A1: Team | B1: Seed | C1: Region | D1: Opponent | E1: Opponent Seed | F1: Barthag | G1: AdjOE | H1: AdjDE | I1: Net Rating (AdjOE-AdjDE) | J1: EFG% | K1: EFGD% | L1: TOR | M1: TORD | N1: ORB | O1: DRB | P1: FTR | Q1: 3P% | R1: 3P%D | S1: Injury Impact Score | T1: AdjOE (recent) | U1: AdjDE (recent) | V1: Net Rating (recent) | W1: Form Score | X1: Adjusted NET | Y1: 3pt Matchup Score | Z1: TO Matchup Score | AA1: Rebounding Matchup Score | AB1: Experience/Coaching Adjustment | AC1: Final Composite Score | AD1: Matchup Key | AE1: Game ID | AF1: Next Game | AG1: Next Slot | AH1: Ready? | AI1: Predicted Winner | AJ1: Prediction Confidence | AK1: Prediction Reason | AL1: Upset Flag | AM1: Winner Advanced? | AN1: Advance Next Game | AO1: Advance Next Slot
A2: Duke | B2: {=IFERROR(INDEX('Team Ratings'!$B$2:$B$73,MATCH($A2,'Team Ratings'!$A$2:$A$73,0)),"")} -> 1 | C2: {=IFERROR(INDEX('Team Ratings'!$C$2:$C$73,MATCH($A2,'Team Ratings'!$A$2:$A$73,0)),"")} -> East | D2: Siena | E2: {=IFERROR(INDEX('Team Ratings'!$B$2:$B$73,MATCH($D2,'Team Ratings'!$A$2:$A$73,0)),"")} -> 16 | F2: {=IFERROR(INDEX('Team Ratings'!$D$2:$D$73,MATCH($A2,'Team Ratings'!$A$2:$A$73,0)),"")} -> 0.9813 | G2: {=IFERROR(INDEX('Team Ratings'!$E$2:$E$73,MATCH($A2,'Team Ratings'!$A$2:$A$73,0)),"")} -> 128.2 | H2: {=IFERROR(INDEX('Team Ratings'!$F$2:$F$73,MATCH($A2,'Team Ratings'!$A$2:$A$73,0)),"")} -> 90.8 | I2: {=IFERROR(INDEX('Team Ratings'!$G$2:$G$73,MATCH($A2,'Team Ratings'!$A$2:$A$73,0)),"")} -> 37.4 | J2: {=IFERROR(INDEX('Team Ratings'!$H$2:$H$73,MATCH($A2,'Team Ratings'!$A$2:$A$73,0)),"")} -> 56.8 | K2: {=IFERROR(INDEX('Team Ratings'!$I$2:$I$73,MATCH($A2,'Team Ratings'!$A$2:$A$73,0)),"")} -> 46.2 | L2: {=IFERROR(INDEX('Team Ratings'!$J$2:$J$73,MATCH($A2,'Team Ratings'!$A$2:$A$73,0)),"")} -> 15.7 | M2: {=IFERROR(INDEX('Team Ratings'!$K$2:$K$73,MATCH($A2,'Team Ratings'!$A$2:$A$73,0)),"")} -> 18.1 | N2: {=IFERROR(INDEX('Team Ratings'!$L$2:$L$73,MATCH($A2,'Team Ratings'!$A$2:$A$73,0)),"")} -> 38.1 | O2: {=IFERROR(INDEX('Team Ratings'!$M$2:$M$73,MATCH($A2,'Team Ratings'!$A$2:$A$73,0)),"")} -> 24.8 | P2: {=IFERROR(INDEX('Team Ratings'!$N$2:$N$73,MATCH($A2,'Team Ratings'!$A$2:$A$73,0)),"")} -> 37.8 | Q2: {=IFERROR(INDEX('Team Ratings'!$O$2:$O$73,MATCH($A2,'Team Ratings'!$A$2:$A$73,0)),"")} -> 35.1 | R2: {=IFERROR(INDEX('Team Ratings'!$P$2:$P$73,MATCH($A2,'Team Ratings'!$A$2:$A$73,0)),"")} -> 30.4 | S2: {=IFERROR(INDEX('Team Ratings'!$Q$2:$Q$73,MATCH($A2,'Team Ratings'!$A$2:$A$73,0)),0)} -> -2.5 | T2: {=IFERROR(INDEX('Team Ratings'!$R$2:$R$73,MATCH($A2,'Team Ratings'!$A$2:$A$73,0)),"")} -> 132.2 | U2: {=IFERROR(INDEX('Team Ratings'!$S$2:$S$73,MATCH($A2,'Team Ratings'!$A$2:$A$73,0)),"")} -> 94.1 | V2: =IF(OR(T2="",U2=""),"",T2-U2) -> 38.1 | W2: =IF(OR(V2="",I2=""),"",V2-I2) -> 0.7 | X2: =IF(OR(I2="",V2=""),"",ROUND((I2*0.75)+(V2*0.25),3)) -> 37.575 | Y2: =IFERROR(ROUND(Q2-INDEX($R$2:$R$65,MATCH($D2,$A$2:$A$65,0)),3),"") -> 2.3 | Z2: =IFERROR(ROUND(M2-INDEX($L$2:$L$65,MATCH($D2,$A$2:$A$65,0)),3),"") -> 2.1 | AA2: =IFERROR(ROUND(MAX(0,MIN(10,5+((N2-INDEX($O$2:$O$65,MATCH($D2,$A$2:$A$65,0)))+(O2-INDEX($N$2:$N$65,MATCH($D2,$A$2:$A$65,0))))/2)),3),"") -> 6 | AB2: =IFERROR(ROUND((1/B2)*4 + (V2/MAX($V$2:$V$65))*4 + (1-(L2/MAX($L$2:$L$65)))*2 + (P2/MAX($P$2:$P$65)) + (O2/MAX($O$2:$O$65)),2),"") -> 9.79 | AC2: =ROUND((0.35*IFERROR((X2-AVERAGE($X$2:$X$65))/_xlfn.STDEV.P($X$2:$X$65),0)) + (0.2*IFERROR((W2-AVERAGE($W$2:$W$65))/_xlfn.STDEV.P($W$2:$W$65),0)) + (0.15*IFERROR((Y2-AVERAGE($Y$2:$Y$65))/_xlfn.STDEV.P($Y$2:$Y$65),0)) + (0.1*IFERROR((Z2-AVERAGE($Z$2:$Z$65))/_xlfn.STDEV.P($Z$2:$Z$65),0)) + (0.1*IFERROR((AA2-AVERAGE($AA$2:$AA$65))/_xlfn.STDEV.P($AA$2:$AA$65),0)) + (0.05*IFERROR((AB2-AVERAGE($AB$2:$AB$65))/_xlfn.STDEV.P($AB$2:$AB$65),0)) + (0.05*IFERROR((S2-AVERAGE($S$2:$S$65))/IF(_xlfn.STDEV.P($S$2:$S$65)=0,1,_xlfn.STDEV.P($S$2:$S$65)),0)),4) -> 0.5997 | AD2: =IF(OR($A2="",$D2=""),"",IF($A2<=$D2,$A2&"|"&$D2,$D2&"|"&$A2)) -> Duke|Siena | AE2: G1 | AF2: G33 | AG2: Team 1 | AH2: =AND($A2<>"",$D2<>"",ISNUMBER($AC2)) -> TRUE | AI2: {=IFERROR(INDEX(Matchups!$N$2:$N$64,MATCH($AE2,Matchups!$A$2:$A$64,0)),"")} -> Duke | AJ2: {=IFERROR(INDEX(Matchups!$O$2:$O$64,MATCH($AE2,Matchups!$A$2:$A$64,0)),"")} -> 64.6 | AK2: {=IFERROR(INDEX(Matchups!$T$2:$T$64,MATCH($AE2,Matchups!$A$2:$A$64,0)),"")} -> ΔComposite=1.22; AdjNET Δ=37.2; 3PT Δ=2.3; TO Δ=0.7; REB Δ=2 | AL2: {=IFERROR(INDEX(Matchups!$P$2:$P$64,MATCH($AE2,Matchups!$A$2:$A$64,0)),"")} | AM2: =IF($AI2="","",IF($A2=$AI2,"Yes","No")) -> Yes | AN2: =IF($AM2="Yes",$AF2,"") -> G33 | AO2: =IF($AM2="Yes",$AG2,"") -> Team 1
A3: Michigan | B3: {=IFERROR(INDEX('Team Ratings'!$B$2:$B$73,MATCH($A3,'Team Ratings'!$A$2:$A$73,0)),"")} -> 1 | C3: {=IFERROR(INDEX('Team Ratings'!$C$2:$C$73,MATCH($A3,'Team Ratings'!$A$2:$A$73,0)),"")} -> Midwest | D3: Howard | E3: {=IFERROR(INDEX('Team Ratings'!$B$2:$B$73,MATCH($D3,'Team Ratings'!$A$2:$A$73,0)),"")} -> 16 | F3: {=IFERROR(INDEX('Team Ratings'!$D$2:$D$73,MATCH($A3,'Team Ratings'!$A$2:$A$73,0)),"")} -> 0.9799 | G3: {=IFERROR(INDEX('Team Ratings'!$E$2:$E$73,MATCH($A3,'Team Ratings'!$A$2:$A$73,0)),"")} -> 127.7 | H3: {=IFERROR(INDEX('Team Ratings'!$F$2:$F$73,MATCH($A3,'Team Ratings'!$A$2:$A$73,0)),"")} -> 91 | I3: {=IFERROR(INDEX('Team Ratings'!$G$2:$G$73,MATCH($A3,'Team Ratings'!$A$2:$A$73,0)),"")} -> 36.7 | J3: {=IFERROR(INDEX('Team Ratings'!$H$2:$H$73,MATCH($A3,'Team Ratings'!$A$2:$A$73,0)),"")} -> 58.1 | K3: {=IFERROR(INDEX('Team Ratings'!$I$2:$I$73,MATCH($A3,'Team Ratings'!$A$2:$A$73,0)),"")} -> 44.7 | L3: {=IFERROR(INDEX('Team Ratings'!$J$2:$J$73,MATCH($A3,'Team Ratings'!$A$2:$A$73,0)),"")} -> 16.7 | M3: {=IFERROR(INDEX('Team Ratings'!$K$2:$K$73,MATCH($A3,'Team Ratings'!$A$2:$A$73,0)),"")} -> 15.5 | N3: {=IFERROR(INDEX('Team Ratings'!$L$2:$L$73,MATCH($A3,'Team Ratings'!$A$2:$A$73,0)),"")} -> 35.4 | O3: {=IFERROR(INDEX('Team Ratings'!$M$2:$M$73,MATCH($A3,'Team Ratings'!$A$2:$A$73,0)),"")} -> 27.7 | P3: {=IFERROR(INDEX('Team Ratings'!$N$2:$N$73,MATCH($A3,'Team Ratings'!$A$2:$A$73,0)),"")} -> 37.7 | Q3: {=IFERROR(INDEX('Team Ratings'!$O$2:$O$73,MATCH($A3,'Team Ratings'!$A$2:$A$73,0)),"")} -> 36 | R3: {=IFERROR(INDEX('Team Ratings'!$P$2:$P$73,MATCH($A3,'Team Ratings'!$A$2:$A$73,0)),"")} -> 30.2 | S3: {=IFERROR(INDEX('Team Ratings'!$Q$2:$Q$73,MATCH($A3,'Team Ratings'!$A$2:$A$73,0)),0)} -> -2 | T3: {=IFERROR(INDEX('Team Ratings'!$R$2:$R$73,MATCH($A3,'Team Ratings'!$A$2:$A$73,0)),"")} -> 121.5 | U3: {=IFERROR(INDEX('Team Ratings'!$S$2:$S$73,MATCH($A3,'Team Ratings'!$A$2:$A$73,0)),"")} -> 93.6 | V3: =IF(OR(T3="",U3=""),"",T3-U3) -> 27.9 | W3: =IF(OR(V3="",I3=""),"",V3-I3) -> -8.8 | X3: =IF(OR(I3="",V3=""),"",ROUND((I3*0.75)+(V3*0.25),3)) -> 34.5 | Y3: =IFERROR(ROUND(Q3-INDEX($R$2:$R$65,MATCH($D3,$A$2:$A$65,0)),3),"") -> 5.6 | Z3: =IFERROR(ROUND(M3-INDEX($L$2:$L$65,MATCH($D3,$A$2:$A$65,0)),3),"") -> -4.3 | AA3: =IFERROR(ROUND(MAX(0,MIN(10,5+((N3-INDEX($O$2:$O$65,MATCH($D3,$A$2:$A$65,0)))+(O3-INDEX($N$2:$N$65,MATCH($D3,$A$2:$A$65,0))))/2)),3),"") -> 2.25 | AB3: =IFERROR(ROUND((1/B3)*4 + (V3/MAX($V$2:$V$65))*4 + (1-(L3/MAX($L$2:$L$65)))*2 + (P3/MAX($P$2:$P$65)) + (O3/MAX($O$2:$O$65)),2),"") -> 8.74 | AC3: =ROUND((0.35*IFERROR((X3-AVERAGE($X$2:$X$65))/_xlfn.STDEV.P($X$2:$X$65),0)) + (0.2*IFERROR((W3-AVERAGE($W$2:$W$65))/_xlfn.STDEV.P($W$2:$W$65),0)) + (0.15*IFERROR((Y3-AVERAGE($Y$2:$Y$65))/_xlfn.STDEV.P($Y$2:$Y$65),0)) + (0.1*IFERROR((Z3-AVERAGE($Z$2:$Z$65))/_xlfn.STDEV.P($Z$2:$Z$65),0)) + (0.1*IFERROR((AA3-AVERAGE($AA$2:$AA$65))/_xlfn.STDEV.P($AA$2:$AA$65),0)) + (0.05*IFERROR((AB3-AVERAGE($AB$2:$AB$65))/_xlfn.STDEV.P($AB$2:$AB$65),0)) + (0.05*IFERROR((S3-AVERAGE($S$2:$S$65))/IF(_xlfn.STDEV.P($S$2:$S$65)=0,1,_xlfn.STDEV.P($S$2:$S$65)),0)),4) -> 0.1536 | AD3: =IF(OR($A3="",$D3=""),"",IF($A3<=$D3,$A3&"|"&$D3,$D3&"|"&$A3)) -> Howard|Michigan | AE3: G25 | AF3: G45 | AG3: Team 1 | AH3: =AND($A3<>"",$D3<>"",ISNUMBER($AC3)) -> TRUE | AI3: {=IFERROR(INDEX(Matchups!$N$2:$N$64,MATCH($AE3,Matchups!$A$2:$A$64,0)),"")} -> Michigan | AJ3: {=IFERROR(INDEX(Matchups!$O$2:$O$64,MATCH($AE3,Matchups!$A$2:$A$64,0)),"")} -> 58 | AK3: {=IFERROR(INDEX(Matchups!$T$2:$T$64,MATCH($AE3,Matchups!$A$2:$A$64,0)),"")} -> ΔComposite=0.67; AdjNET Δ=-37.9; 3PT Δ=-1.1; TO Δ=8.9; REB Δ=5.5 | AL3: {=IFERROR(INDEX(Matchups!$P$2:$P$64,MATCH($AE3,Matchups!$A$2:$A$64,0)),"")} | AM3: =IF($AI3="","",IF($A3=$AI3,"Yes","No")) -> Yes | AN3: =IF($AM3="Yes",$AF3,"") -> G45 | AO3: =IF($AM3="Yes",$AG3,"") -> Team 1
A4: Florida | B4: {=IFERROR(INDEX('Team Ratings'!$B$2:$B$73,MATCH($A4,'Team Ratings'!$A$2:$A$73,0)),"")} -> 1 | C4: {=IFERROR(INDEX('Team Ratings'!$C$2:$C$73,MATCH($A4,'Team Ratings'!$A$2:$A$73,0)),"")} -> South | D4: Prairie View A&M | E4: {=IFERROR(INDEX('Team Ratings'!$B$2:$B$73,MATCH($D4,'Team Ratings'!$A$2:$A$73,0)),"")} -> 16 | F4: {=IFERROR(INDEX('Team Ratings'!$D$2:$D$73,MATCH($A4,'Team Ratings'!$A$2:$A$73,0)),"")} -> 0.9732 | G4: {=IFERROR(INDEX('Team Ratings'!$E$2:$E$73,MATCH($A4,'Team Ratings'!$A$2:$A$73,0)),"")} -> 126.1 | H4: {=IFERROR(INDEX('Team Ratings'!$F$2:$F$73,MATCH($A4,'Team Ratings'!$A$2:$A$73,0)),"")} -> 92.3 | I4: {=IFERROR(INDEX('Team Ratings'!$G$2:$G$73,MATCH($A4,'Team Ratings'!$A$2:$A$73,0)),"")} -> 33.8 | J4: {=IFERROR(INDEX('Team Ratings'!$H$2:$H$73,MATCH($A4,'Team Ratings'!$A$2:$A$73,0)),"")} -> 53.5 | K4: {=IFERROR(INDEX('Team Ratings'!$I$2:$I$73,MATCH($A4,'Team Ratings'!$A$2:$A$73,0)),"")} -> 46.3 | L4: {=IFERROR(INDEX('Team Ratings'!$J$2:$J$73,MATCH($A4,'Team Ratings'!$A$2:$A$73,0)),"")} -> 16.5 | M4: {=IFERROR(INDEX('Team Ratings'!$K$2:$K$73,MATCH($A4,'Team Ratings'!$A$2:$A$73,0)),"")} -> 15.4 | N4: {=IFERROR(INDEX('Team Ratings'!$L$2:$L$73,MATCH($A4,'Team Ratings'!$A$2:$A$73,0)),"")} -> 43.2 | O4: {=IFERROR(INDEX('Team Ratings'!$M$2:$M$73,MATCH($A4,'Team Ratings'!$A$2:$A$73,0)),"")} -> 24.8 | P4: {=IFERROR(INDEX('Team Ratings'!$N$2:$N$73,MATCH($A4,'Team Ratings'!$A$2:$A$73,0)),"")} -> 39.1 | Q4: {=IFERROR(INDEX('Team Ratings'!$O$2:$O$73,MATCH($A4,'Team Ratings'!$A$2:$A$73,0)),"")} -> 30.8 | R4: {=IFERROR(INDEX('Team Ratings'!$P$2:$P$73,MATCH($A4,'Team Ratings'!$A$2:$A$73,0)),"")} -> 32.4 | S4: {=IFERROR(INDEX('Team Ratings'!$Q$2:$Q$73,MATCH($A4,'Team Ratings'!$A$2:$A$73,0)),0)} -> 0 | T4: {=IFERROR(INDEX('Team Ratings'!$R$2:$R$73,MATCH($A4,'Team Ratings'!$A$2:$A$73,0)),"")} -> 127.1 | U4: {=IFERROR(INDEX('Team Ratings'!$S$2:$S$73,MATCH($A4,'Team Ratings'!$A$2:$A$73,0)),"")} -> 98.8 | V4: =IF(OR(T4="",U4=""),"",T4-U4) -> 28.3 | W4: =IF(OR(V4="",I4=""),"",V4-I4) -> -5.5 | X4: =IF(OR(I4="",V4=""),"",ROUND((I4*0.75)+(V4*0.25),3)) -> 32.425 | Y4: =IFERROR(ROUND(Q4-INDEX($R$2:$R$65,MATCH($D4,$A$2:$A$65,0)),3),"") -> -4.2 | Z4: =IFERROR(ROUND(M4-INDEX($L$2:$L$65,MATCH($D4,$A$2:$A$65,0)),3),"") -> -0.6 | AA4: =IFERROR(ROUND(MAX(0,MIN(10,5+((N4-INDEX($O$2:$O$65,MATCH($D4,$A$2:$A$65,0)))+(O4-INDEX($N$2:$N$65,MATCH($D4,$A$2:$A$65,0))))/2)),3),"") -> 8.05 | AB4: =IFERROR(ROUND((1/B4)*4 + (V4/MAX($V$2:$V$65))*4 + (1-(L4/MAX($L$2:$L$65)))*2 + (P4/MAX($P$2:$P$65)) + (O4/MAX($O$2:$O$65)),2),"") -> 8.75 | AC4: =ROUND((0.35*IFERROR((X4-AVERAGE($X$2:$X$65))/_xlfn.STDEV.P($X$2:$X$65),0)) + (0.2*IFERROR((W4-AVERAGE($W$2:$W$65))/_xlfn.STDEV.P($W$2:$W$65),0)) + (0.15*IFERROR((Y4-AVERAGE($Y$2:$Y$65))/_xlfn.STDEV.P($Y$2:$Y$65),0)) + (0.1*IFERROR((Z4-AVERAGE($Z$2:$Z$65))/_xlfn.STDEV.P($Z$2:$Z$65),0)) + (0.1*IFERROR((AA4-AVERAGE($AA$2:$AA$65))/_xlfn.STDEV.P($AA$2:$AA$65),0)) + (0.05*IFERROR((AB4-AVERAGE($AB$2:$AB$65))/_xlfn.STDEV.P($AB$2:$AB$65),0)) + (0.05*IFERROR((S4-AVERAGE($S$2:$S$65))/IF(_xlfn.STDEV.P($S$2:$S$65)=0,1,_xlfn.STDEV.P($S$2:$S$65)),0)),4) -> 0.0299 | AD4: =IF(OR($A4="",$D4=""),"",IF($A4<=$D4,$A4&"|"&$D4,$D4&"|"&$A4)) -> Florida|Prairie View A&M | AE4: G17 | AF4: G41 | AG4: Team 1 | AH4: =AND($A4<>"",$D4<>"",ISNUMBER($AC4)) -> TRUE | AI4: {=IFERROR(INDEX(Matchups!$N$2:$N$64,MATCH($AE4,Matchups!$A$2:$A$64,0)),"")} -> Florida | AJ4: {=IFERROR(INDEX(Matchups!$O$2:$O$64,MATCH($AE4,Matchups!$A$2:$A$64,0)),"")} -> 58.3 | AK4: {=IFERROR(INDEX(Matchups!$T$2:$T$64,MATCH($AE4,Matchups!$A$2:$A$64,0)),"")} -> ΔComposite=0.69; AdjNET Δ=-38.7; 3PT Δ=5; TO Δ=3.2; REB Δ=-6.1 | AL4: {=IFERROR(INDEX(Matchups!$P$2:$P$64,MATCH($AE4,Matchups!$A$2:$A$64,0)),"")} | AM4: =IF($AI4="","",IF($A4=$AI4,"Yes","No")) -> Yes | AN4: =IF($AM4="Yes",$AF4,"") -> G41 | AO4: =IF($AM4="Yes",$AG4,"") -> Team 1
A5: Arizona | B5: {=IFERROR(INDEX('Team Ratings'!$B$2:$B$73,MATCH($A5,'Team Ratings'!$A$2:$A$73,0)),"")} -> 1 | C5: {=IFERROR(INDEX('Team Ratings'!$C$2:$C$73,MATCH($A5,'Team Ratings'!$A$2:$A$73,0)),"")} -> West | D5: LIU | E5: {=IFERROR(INDEX('Team Ratings'!$B$2:$B$73,MATCH($D5,'Team Ratings'!$A$2:$A$73,0)),"")} -> 16 | F5: {=IFERROR(INDEX('Team Ratings'!$D$2:$D$73,MATCH($A5,'Team Ratings'!$A$2:$A$73,0)),"")} -> 0.9776 | G5: {=IFERROR(INDEX('Team Ratings'!$E$2:$E$73,MATCH($A5,'Team Ratings'!$A$2:$A$73,0)),"")} -> 126.9 | H5: {=IFERROR(INDEX('Team Ratings'!$F$2:$F$73,MATCH($A5,'Team Ratings'!$A$2:$A$73,0)),"")} -> 91.4 | I5: {=IFERROR(INDEX('Team Ratings'!$G$2:$G$73,MATCH($A5,'Team Ratings'!$A$2:$A$73,0)),"")} -> 35.5 | J5: {=IFERROR(INDEX('Team Ratings'!$H$2:$H$73,MATCH($A5,'Team Ratings'!$A$2:$A$73,0)),"")} -> 55.1 | K5: {=IFERROR(INDEX('Team Ratings'!$I$2:$I$73,MATCH($A5,'Team Ratings'!$A$2:$A$73,0)),"")} -> 45 | L5: {=IFERROR(INDEX('Team Ratings'!$J$2:$J$73,MATCH($A5,'Team Ratings'!$A$2:$A$73,0)),"")} -> 15.1 | M5: {=IFERROR(INDEX('Team Ratings'!$K$2:$K$73,MATCH($A5,'Team Ratings'!$A$2:$A$73,0)),"")} -> 16.7 | N5: {=IFERROR(INDEX('Team Ratings'!$L$2:$L$73,MATCH($A5,'Team Ratings'!$A$2:$A$73,0)),"")} -> 38.1 | O5: {=IFERROR(INDEX('Team Ratings'!$M$2:$M$73,MATCH($A5,'Team Ratings'!$A$2:$A$73,0)),"")} -> 26.9 | P5: {=IFERROR(INDEX('Team Ratings'!$N$2:$N$73,MATCH($A5,'Team Ratings'!$A$2:$A$73,0)),"")} -> 42.9 | Q5: {=IFERROR(INDEX('Team Ratings'!$O$2:$O$73,MATCH($A5,'Team Ratings'!$A$2:$A$73,0)),"")} -> 36 | R5: {=IFERROR(INDEX('Team Ratings'!$P$2:$P$73,MATCH($A5,'Team Ratings'!$A$2:$A$73,0)),"")} -> 31.4 | S5: {=IFERROR(INDEX('Team Ratings'!$Q$2:$Q$73,MATCH($A5,'Team Ratings'!$A$2:$A$73,0)),0)} -> 0 | T5: {=IFERROR(INDEX('Team Ratings'!$R$2:$R$73,MATCH($A5,'Team Ratings'!$A$2:$A$73,0)),"")} -> 131.9 | U5: {=IFERROR(INDEX('Team Ratings'!$S$2:$S$73,MATCH($A5,'Team Ratings'!$A$2:$A$73,0)),"")} -> 92.3 | V5: =IF(OR(T5="",U5=""),"",T5-U5) -> 39.6 | W5: =IF(OR(V5="",I5=""),"",V5-I5) -> 4.1 | X5: =IF(OR(I5="",V5=""),"",ROUND((I5*0.75)+(V5*0.25),3)) -> 36.525 | Y5: =IFERROR(ROUND(Q5-INDEX($R$2:$R$65,MATCH($D5,$A$2:$A$65,0)),3),"") -> 4.1 | Z5: =IFERROR(ROUND(M5-INDEX($L$2:$L$65,MATCH($D5,$A$2:$A$65,0)),3),"") -> -2.3 | AA5: =IFERROR(ROUND(MAX(0,MIN(10,5+((N5-INDEX($O$2:$O$65,MATCH($D5,$A$2:$A$65,0)))+(O5-INDEX($N$2:$N$65,MATCH($D5,$A$2:$A$65,0))))/2)),3),"") -> 4.05 | AB5: =IFERROR(ROUND((1/B5)*4 + (V5/MAX($V$2:$V$65))*4 + (1-(L5/MAX($L$2:$L$65)))*2 + (P5/MAX($P$2:$P$65)) + (O5/MAX($O$2:$O$65)),2),"") -> 10.17 | AC5: =ROUND((0.35*IFERROR((X5-AVERAGE($X$2:$X$65))/_xlfn.STDEV.P($X$2:$X$65),0)) + (0.2*IFERROR((W5-AVERAGE($W$2:$W$65))/_xlfn.STDEV.P($W$2:$W$65),0)) + (0.15*IFERROR((Y5-AVERAGE($Y$2:$Y$65))/_xlfn.STDEV.P($Y$2:$Y$65),0)) + (0.1*IFERROR((Z5-AVERAGE($Z$2:$Z$65))/_xlfn.STDEV.P($Z$2:$Z$65),0)) + (0.1*IFERROR((AA5-AVERAGE($AA$2:$AA$65))/_xlfn.STDEV.P($AA$2:$AA$65),0)) + (0.05*IFERROR((AB5-AVERAGE($AB$2:$AB$65))/_xlfn.STDEV.P($AB$2:$AB$65),0)) + (0.05*IFERROR((S5-AVERAGE($S$2:$S$65))/IF(_xlfn.STDEV.P($S$2:$S$65)=0,1,_xlfn.STDEV.P($S$2:$S$65)),0)),4) -> 0.7509 | AD5: =IF(OR($A5="",$D5=""),"",IF($A5<=$D5,$A5&"|"&$D5,$D5&"|"&$A5)) -> Arizona|LIU | AE5: G9 | AF5: G37 | AG5: Team 1 | AH5: =AND($A5<>"",$D5<>"",ISNUMBER($AC5)) -> TRUE | AI5: {=IFERROR(INDEX(Matchups!$N$2:$N$64,MATCH($AE5,Matchups!$A$2:$A$64,0)),"")} -> Arizona | AJ5: {=IFERROR(INDEX(Matchups!$O$2:$O$64,MATCH($AE5,Matchups!$A$2:$A$64,0)),"")} -> 67.4 | AK5: {=IFERROR(INDEX(Matchups!$T$2:$T$64,MATCH($AE5,Matchups!$A$2:$A$64,0)),"")} -> ΔComposite=1.45; AdjNET Δ=43.3; 3PT Δ=-0.6; TO Δ=-6.1; REB Δ=-1.9 | AL5: {=IFERROR(INDEX(Matchups!$P$2:$P$64,MATCH($AE5,Matchups!$A$2:$A$64,0)),"")} | AM5: =IF($AI5="","",IF($A5=$AI5,"Yes","No")) -> Yes | AN5: =IF($AM5="Yes",$AF5,"") -> G37 | AO5: =IF($AM5="Yes",$AG5,"") -> Team 1
A6: Connecticut | B6: {=IFERROR(INDEX('Team Ratings'!$B$2:$B$73,MATCH($A6,'Team Ratings'!$A$2:$A$73,0)),"")} -> 2 | C6: {=IFERROR(INDEX('Team Ratings'!$C$2:$C$73,MATCH($A6,'Team Ratings'!$A$2:$A$73,0)),"")} -> East | D6: Furman | E6: {=IFERROR(INDEX('Team Ratings'!$B$2:$B$73,MATCH($D6,'Team Ratings'!$A$2:$A$73,0)),"")} -> 15 | F6: {=IFERROR(INDEX('Team Ratings'!$D$2:$D$73,MATCH($A6,'Team Ratings'!$A$2:$A$73,0)),"")} -> 0.9517 | G6: {=IFERROR(INDEX('Team Ratings'!$E$2:$E$73,MATCH($A6,'Team Ratings'!$A$2:$A$73,0)),"")} -> 123.1 | H6: {=IFERROR(INDEX('Team Ratings'!$F$2:$F$73,MATCH($A6,'Team Ratings'!$A$2:$A$73,0)),"")} -> 95 | I6: {=IFERROR(INDEX('Team Ratings'!$G$2:$G$73,MATCH($A6,'Team Ratings'!$A$2:$A$73,0)),"")} -> 28.1 | J6: {=IFERROR(INDEX('Team Ratings'!$H$2:$H$73,MATCH($A6,'Team Ratings'!$A$2:$A$73,0)),"")} -> 55.3 | K6: {=IFERROR(INDEX('Team Ratings'!$I$2:$I$73,MATCH($A6,'Team Ratings'!$A$2:$A$73,0)),"")} -> 45.7 | L6: {=IFERROR(INDEX('Team Ratings'!$J$2:$J$73,MATCH($A6,'Team Ratings'!$A$2:$A$73,0)),"")} -> 16.8 | M6: {=IFERROR(INDEX('Team Ratings'!$K$2:$K$73,MATCH($A6,'Team Ratings'!$A$2:$A$73,0)),"")} -> 18 | N6: {=IFERROR(INDEX('Team Ratings'!$L$2:$L$73,MATCH($A6,'Team Ratings'!$A$2:$A$73,0)),"")} -> 35.7 | O6: {=IFERROR(INDEX('Team Ratings'!$M$2:$M$73,MATCH($A6,'Team Ratings'!$A$2:$A$73,0)),"")} -> 28.7 | P6: {=IFERROR(INDEX('Team Ratings'!$N$2:$N$73,MATCH($A6,'Team Ratings'!$A$2:$A$73,0)),"")} -> 30 | Q6: {=IFERROR(INDEX('Team Ratings'!$O$2:$O$73,MATCH($A6,'Team Ratings'!$A$2:$A$73,0)),"")} -> 35.2 | R6: {=IFERROR(INDEX('Team Ratings'!$P$2:$P$73,MATCH($A6,'Team Ratings'!$A$2:$A$73,0)),"")} -> 30.3 | S6: {=IFERROR(INDEX('Team Ratings'!$Q$2:$Q$73,MATCH($A6,'Team Ratings'!$A$2:$A$73,0)),0)} -> 0 | T6: {=IFERROR(INDEX('Team Ratings'!$R$2:$R$73,MATCH($A6,'Team Ratings'!$A$2:$A$73,0)),"")} -> 114.9 | U6: {=IFERROR(INDEX('Team Ratings'!$S$2:$S$73,MATCH($A6,'Team Ratings'!$A$2:$A$73,0)),"")} -> 95.4 | V6: =IF(OR(T6="",U6=""),"",T6-U6) -> 19.5 | W6: =IF(OR(V6="",I6=""),"",V6-I6) -> -8.6 | X6: =IF(OR(I6="",V6=""),"",ROUND((I6*0.75)+(V6*0.25),3)) -> 25.95 | Y6: =IFERROR(ROUND(Q6-INDEX($R$2:$R$65,MATCH($D6,$A$2:$A$65,0)),3),"") -> 2.6 | Z6: =IFERROR(ROUND(M6-INDEX($L$2:$L$65,MATCH($D6,$A$2:$A$65,0)),3),"") -> 0.2 | AA6: =IFERROR(ROUND(MAX(0,MIN(10,5+((N6-INDEX($O$2:$O$65,MATCH($D6,$A$2:$A$65,0)))+(O6-INDEX($N$2:$N$65,MATCH($D6,$A$2:$A$65,0))))/2)),3),"") -> 7.95 | AB6: =IFERROR(ROUND((1/B6)*4 + (V6/MAX($V$2:$V$65))*4 + (1-(L6/MAX($L$2:$L$65)))*2 + (P6/MAX($P$2:$P$65)) + (O6/MAX($O$2:$O$65)),2),"") -> 5.74 | AC6: =ROUND((0.35*IFERROR((X6-AVERAGE($X$2:$X$65))/_xlfn.STDEV.P($X$2:$X$65),0)) + (0.2*IFERROR((W6-AVERAGE($W$2:$W$65))/_xlfn.STDEV.P($W$2:$W$65),0)) + (0.15*IFERROR((Y6-AVERAGE($Y$2:$Y$65))/_xlfn.STDEV.P($Y$2:$Y$65),0)) + (0.1*IFERROR((Z6-AVERAGE($Z$2:$Z$65))/_xlfn.STDEV.P($Z$2:$Z$65),0)) + (0.1*IFERROR((AA6-AVERAGE($AA$2:$AA$65))/_xlfn.STDEV.P($AA$2:$AA$65),0)) + (0.05*IFERROR((AB6-AVERAGE($AB$2:$AB$65))/_xlfn.STDEV.P($AB$2:$AB$65),0)) + (0.05*IFERROR((S6-AVERAGE($S$2:$S$65))/IF(_xlfn.STDEV.P($S$2:$S$65)=0,1,_xlfn.STDEV.P($S$2:$S$65)),0)),4) -> 0.1263 | AD6: =IF(OR($A6="",$D6=""),"",IF($A6<=$D6,$A6&"|"&$D6,$D6&"|"&$A6)) -> Connecticut|Furman | AE6: G8 | AF6: G36 | AG6: Team 2 | AH6: =AND($A6<>"",$D6<>"",ISNUMBER($AC6)) -> TRUE | AI6: {=IFERROR(INDEX(Matchups!$N$2:$N$64,MATCH($AE6,Matchups!$A$2:$A$64,0)),"")} -> Connecticut | AJ6: {=IFERROR(INDEX(Matchups!$O$2:$O$64,MATCH($AE6,Matchups!$A$2:$A$64,0)),"")} -> 60.5 | AK6: {=IFERROR(INDEX(Matchups!$T$2:$T$64,MATCH($AE6,Matchups!$A$2:$A$64,0)),"")} -> ΔComposite=0.88; AdjNET Δ=-26.6; 3PT Δ=0.4; TO Δ=-3.3; REB Δ=-5.9 | AL6: {=IFERROR(INDEX(Matchups!$P$2:$P$64,MATCH($AE6,Matchups!$A$2:$A$64,0)),"")} | AM6: =IF($AI6="","",IF($A6=$AI6,"Yes","No")) -> Yes | AN6: =IF($AM6="Yes",$AF6,"") -> G36 | AO6: =IF($AM6="Yes",$AG6,"") -> Team 2
A7: Iowa St. | B7: {=IFERROR(INDEX('Team Ratings'!$B$2:$B$73,MATCH($A7,'Team Ratings'!$A$2:$A$73,0)),"")} -> 2 | C7: {=IFERROR(INDEX('Team Ratings'!$C$2:$C$73,MATCH($A7,'Team Ratings'!$A$2:$A$73,0)),"")} -> Midwest | D7: Tennessee St. | E7: {=IFERROR(INDEX('Team Ratings'!$B$2:$B$73,MATCH($D7,'Team Ratings'!$A$2:$A$73,0)),"")} -> 15 | F7: {=IFERROR(INDEX('Team Ratings'!$D$2:$D$73,MATCH($A7,'Team Ratings'!$A$2:$A$73,0)),"")} -> 0.9655 | G7: {=IFERROR(INDEX('Team Ratings'!$E$2:$E$73,MATCH($A7,'Team Ratings'!$A$2:$A$73,0)),"")} -> 123.8 | H7: {=IFERROR(INDEX('Team Ratings'!$F$2:$F$73,MATCH($A7,'Team Ratings'!$A$2:$A$73,0)),"")} -> 92.6 | I7: {=IFERROR(INDEX('Team Ratings'!$G$2:$G$73,MATCH($A7,'Team Ratings'!$A$2:$A$73,0)),"")} -> 31.2 | J7: {=IFERROR(INDEX('Team Ratings'!$H$2:$H$73,MATCH($A7,'Team Ratings'!$A$2:$A$73,0)),"")} -> 56.5 | K7: {=IFERROR(INDEX('Team Ratings'!$I$2:$I$73,MATCH($A7,'Team Ratings'!$A$2:$A$73,0)),"")} -> 49.5 | L7: {=IFERROR(INDEX('Team Ratings'!$J$2:$J$73,MATCH($A7,'Team Ratings'!$A$2:$A$73,0)),"")} -> 15.1 | M7: {=IFERROR(INDEX('Team Ratings'!$K$2:$K$73,MATCH($A7,'Team Ratings'!$A$2:$A$73,0)),"")} -> 22.4 | N7: {=IFERROR(INDEX('Team Ratings'!$L$2:$L$73,MATCH($A7,'Team Ratings'!$A$2:$A$73,0)),"")} -> 35.3 | O7: {=IFERROR(INDEX('Team Ratings'!$M$2:$M$73,MATCH($A7,'Team Ratings'!$A$2:$A$73,0)),"")} -> 28.1 | P7: {=IFERROR(INDEX('Team Ratings'!$N$2:$N$73,MATCH($A7,'Team Ratings'!$A$2:$A$73,0)),"")} -> 34 | Q7: {=IFERROR(INDEX('Team Ratings'!$O$2:$O$73,MATCH($A7,'Team Ratings'!$A$2:$A$73,0)),"")} -> 38.7 | R7: {=IFERROR(INDEX('Team Ratings'!$P$2:$P$73,MATCH($A7,'Team Ratings'!$A$2:$A$73,0)),"")} -> 32.1 | S7: {=IFERROR(INDEX('Team Ratings'!$Q$2:$Q$73,MATCH($A7,'Team Ratings'!$A$2:$A$73,0)),0)} -> 0 | T7: {=IFERROR(INDEX('Team Ratings'!$R$2:$R$73,MATCH($A7,'Team Ratings'!$A$2:$A$73,0)),"")} -> 124.8 | U7: {=IFERROR(INDEX('Team Ratings'!$S$2:$S$73,MATCH($A7,'Team Ratings'!$A$2:$A$73,0)),"")} -> 85.5 | V7: =IF(OR(T7="",U7=""),"",T7-U7) -> 39.3 | W7: =IF(OR(V7="",I7=""),"",V7-I7) -> 8.1 | X7: =IF(OR(I7="",V7=""),"",ROUND((I7*0.75)+(V7*0.25),3)) -> 33.225 | Y7: =IFERROR(ROUND(Q7-INDEX($R$2:$R$65,MATCH($D7,$A$2:$A$65,0)),3),"") -> 5.2 | Z7: =IFERROR(ROUND(M7-INDEX($L$2:$L$65,MATCH($D7,$A$2:$A$65,0)),3),"") -> 5.9 | AA7: =IFERROR(ROUND(MAX(0,MIN(10,5+((N7-INDEX($O$2:$O$65,MATCH($D7,$A$2:$A$65,0)))+(O7-INDEX($N$2:$N$65,MATCH($D7,$A$2:$A$65,0))))/2)),3),"") -> 4.3 | AB7: =IFERROR(ROUND((1/B7)*4 + (V7/MAX($V$2:$V$65))*4 + (1-(L7/MAX($L$2:$L$65)))*2 + (P7/MAX($P$2:$P$65)) + (O7/MAX($O$2:$O$65)),2),"") -> 7.98 | AC7: =ROUND((0.35*IFERROR((X7-AVERAGE($X$2:$X$65))/_xlfn.STDEV.P($X$2:$X$65),0)) + (0.2*IFERROR((W7-AVERAGE($W$2:$W$65))/_xlfn.STDEV.P($W$2:$W$65),0)) + (0.15*IFERROR((Y7-AVERAGE($Y$2:$Y$65))/_xlfn.STDEV.P($Y$2:$Y$65),0)) + (0.1*IFERROR((Z7-AVERAGE($Z$2:$Z$65))/_xlfn.STDEV.P($Z$2:$Z$65),0)) + (0.1*IFERROR((AA7-AVERAGE($AA$2:$AA$65))/_xlfn.STDEV.P($AA$2:$AA$65),0)) + (0.05*IFERROR((AB7-AVERAGE($AB$2:$AB$65))/_xlfn.STDEV.P($AB$2:$AB$65),0)) + (0.05*IFERROR((S7-AVERAGE($S$2:$S$65))/IF(_xlfn.STDEV.P($S$2:$S$65)=0,1,_xlfn.STDEV.P($S$2:$S$65)),0)),4) -> 1.0369 | AD7: =IF(OR($A7="",$D7=""),"",IF($A7<=$D7,$A7&"|"&$D7,$D7&"|"&$A7)) -> Iowa St.|Tennessee St. | AE7: G32 | AF7: G48 | AG7: Team 2 | AH7: =AND($A7<>"",$D7<>"",ISNUMBER($AC7)) -> TRUE | AI7: {=IFERROR(INDEX(Matchups!$N$2:$N$64,MATCH($AE7,Matchups!$A$2:$A$64,0)),"")} -> Iowa St. | AJ7: {=IFERROR(INDEX(Matchups!$O$2:$O$64,MATCH($AE7,Matchups!$A$2:$A$64,0)),"")} -> 61.2 | AK7: {=IFERROR(INDEX(Matchups!$T$2:$T$64,MATCH($AE7,Matchups!$A$2:$A$64,0)),"")} -> ΔComposite=0.93; AdjNET Δ=31.4; 3PT Δ=3.6; TO Δ=1; REB Δ=-1.4 | AL7: {=IFERROR(INDEX(Matchups!$P$2:$P$64,MATCH($AE7,Matchups!$A$2:$A$64,0)),"")} | AM7: =IF($AI7="","",IF($A7=$AI7,"Yes","No")) -> Yes | AN7: =IF($AM7="Yes",$AF7,"") -> G48 | AO7: =IF($AM7="Yes",$AG7,"") -> Team 2
A8: Houston | B8: {=IFERROR(INDEX('Team Ratings'!$B$2:$B$73,MATCH($A8,'Team Ratings'!$A$2:$A$73,0)),"")} -> 2 | C8: {=IFERROR(INDEX('Team Ratings'!$C$2:$C$73,MATCH($A8,'Team Ratings'!$A$2:$A$73,0)),"")} -> South | D8: Idaho | E8: {=IFERROR(INDEX('Team Ratings'!$B$2:$B$73,MATCH($D8,'Team Ratings'!$A$2:$A$73,0)),"")} -> 15 | F8: {=IFERROR(INDEX('Team Ratings'!$D$2:$D$73,MATCH($A8,'Team Ratings'!$A$2:$A$73,0)),"")} -> 0.9709 | G8: {=IFERROR(INDEX('Team Ratings'!$E$2:$E$73,MATCH($A8,'Team Ratings'!$A$2:$A$73,0)),"")} -> 125.3 | H8: {=IFERROR(INDEX('Team Ratings'!$F$2:$F$73,MATCH($A8,'Team Ratings'!$A$2:$A$73,0)),"")} -> 92.4 | I8: {=IFERROR(INDEX('Team Ratings'!$G$2:$G$73,MATCH($A8,'Team Ratings'!$A$2:$A$73,0)),"")} -> 32.9 | J8: {=IFERROR(INDEX('Team Ratings'!$H$2:$H$73,MATCH($A8,'Team Ratings'!$A$2:$A$73,0)),"")} -> 52.1 | K8: {=IFERROR(INDEX('Team Ratings'!$I$2:$I$73,MATCH($A8,'Team Ratings'!$A$2:$A$73,0)),"")} -> 46.6 | L8: {=IFERROR(INDEX('Team Ratings'!$J$2:$J$73,MATCH($A8,'Team Ratings'!$A$2:$A$73,0)),"")} -> 13 | M8: {=IFERROR(INDEX('Team Ratings'!$K$2:$K$73,MATCH($A8,'Team Ratings'!$A$2:$A$73,0)),"")} -> 21 | N8: {=IFERROR(INDEX('Team Ratings'!$L$2:$L$73,MATCH($A8,'Team Ratings'!$A$2:$A$73,0)),"")} -> 35.9 | O8: {=IFERROR(INDEX('Team Ratings'!$M$2:$M$73,MATCH($A8,'Team Ratings'!$A$2:$A$73,0)),"")} -> 30.9 | P8: {=IFERROR(INDEX('Team Ratings'!$N$2:$N$73,MATCH($A8,'Team Ratings'!$A$2:$A$73,0)),"")} -> 26.9 | Q8: {=IFERROR(INDEX('Team Ratings'!$O$2:$O$73,MATCH($A8,'Team Ratings'!$A$2:$A$73,0)),"")} -> 34.9 | R8: {=IFERROR(INDEX('Team Ratings'!$P$2:$P$73,MATCH($A8,'Team Ratings'!$A$2:$A$73,0)),"")} -> 32.1 | S8: {=IFERROR(INDEX('Team Ratings'!$Q$2:$Q$73,MATCH($A8,'Team Ratings'!$A$2:$A$73,0)),0)} -> -1 | T8: {=IFERROR(INDEX('Team Ratings'!$R$2:$R$73,MATCH($A8,'Team Ratings'!$A$2:$A$73,0)),"")} -> 121.8 | U8: {=IFERROR(INDEX('Team Ratings'!$S$2:$S$73,MATCH($A8,'Team Ratings'!$A$2:$A$73,0)),"")} -> 92.6 | V8: =IF(OR(T8="",U8=""),"",T8-U8) -> 29.2 | W8: =IF(OR(V8="",I8=""),"",V8-I8) -> -3.7 | X8: =IF(OR(I8="",V8=""),"",ROUND((I8*0.75)+(V8*0.25),3)) -> 31.975 | Y8: =IFERROR(ROUND(Q8-INDEX($R$2:$R$65,MATCH($D8,$A$2:$A$65,0)),3),"") -> 0.1 | Z8: =IFERROR(ROUND(M8-INDEX($L$2:$L$65,MATCH($D8,$A$2:$A$65,0)),3),"") -> 6 | AA8: =IFERROR(ROUND(MAX(0,MIN(10,5+((N8-INDEX($O$2:$O$65,MATCH($D8,$A$2:$A$65,0)))+(O8-INDEX($N$2:$N$65,MATCH($D8,$A$2:$A$65,0))))/2)),3),"") -> 10 | AB8: =IFERROR(ROUND((1/B8)*4 + (V8/MAX($V$2:$V$65))*4 + (1-(L8/MAX($L$2:$L$65)))*2 + (P8/MAX($P$2:$P$65)) + (O8/MAX($O$2:$O$65)),2),"") -> 7.1 | AC8: =ROUND((0.35*IFERROR((X8-AVERAGE($X$2:$X$65))/_xlfn.STDEV.P($X$2:$X$65),0)) + (0.2*IFERROR((W8-AVERAGE($W$2:$W$65))/_xlfn.STDEV.P($W$2:$W$65),0)) + (0.15*IFERROR((Y8-AVERAGE($Y$2:$Y$65))/_xlfn.STDEV.P($Y$2:$Y$65),0)) + (0.1*IFERROR((Z8-AVERAGE($Z$2:$Z$65))/_xlfn.STDEV.P($Z$2:$Z$65),0)) + (0.1*IFERROR((AA8-AVERAGE($AA$2:$AA$65))/_xlfn.STDEV.P($AA$2:$AA$65),0)) + (0.05*IFERROR((AB8-AVERAGE($AB$2:$AB$65))/_xlfn.STDEV.P($AB$2:$AB$65),0)) + (0.05*IFERROR((S8-AVERAGE($S$2:$S$65))/IF(_xlfn.STDEV.P($S$2:$S$65)=0,1,_xlfn.STDEV.P($S$2:$S$65)),0)),4) -> 0.4975 | AD8: =IF(OR($A8="",$D8=""),"",IF($A8<=$D8,$A8&"|"&$D8,$D8&"|"&$A8)) -> Houston|Idaho | AE8: G24 | AF8: G44 | AG8: Team 2 | AH8: =AND($A8<>"",$D8<>"",ISNUMBER($AC8)) -> TRUE | AI8: {=IFERROR(INDEX(Matchups!$N$2:$N$64,MATCH($AE8,Matchups!$A$2:$A$64,0)),"")} -> Houston | AJ8: {=IFERROR(INDEX(Matchups!$O$2:$O$64,MATCH($AE8,Matchups!$A$2:$A$64,0)),"")} -> 60 | AK8: {=IFERROR(INDEX(Matchups!$T$2:$T$64,MATCH($AE8,Matchups!$A$2:$A$64,0)),"")} -> ΔComposite=0.83; AdjNET Δ=26.6; 3PT Δ=-2.3; TO Δ=3.8; REB Δ=10 | AL8: {=IFERROR(INDEX(Matchups!$P$2:$P$64,MATCH($AE8,Matchups!$A$2:$A$64,0)),"")} | AM8: =IF($AI8="","",IF($A8=$AI8,"Yes","No")) -> Yes | AN8: =IF($AM8="Yes",$AF8,"") -> G44 | AO8: =IF($AM8="Yes",$AG8,"") -> Team 2
A9: Purdue | B9: {=IFERROR(INDEX('Team Ratings'!$B$2:$B$73,MATCH($A9,'Team Ratings'!$A$2:$A$73,0)),"")} -> 2 | C9: {=IFERROR(INDEX('Team Ratings'!$C$2:$C$73,MATCH($A9,'Team Ratings'!$A$2:$A$73,0)),"")} -> West | D9: Queens | E9: {=IFERROR(INDEX('Team Ratings'!$B$2:$B$73,MATCH($D9,'Team Ratings'!$A$2:$A$73,0)),"")} -> 15 | F9: {=IFERROR(INDEX('Team Ratings'!$D$2:$D$73,MATCH($A9,'Team Ratings'!$A$2:$A$73,0)),"")} -> 0.9636 | G9: {=IFERROR(INDEX('Team Ratings'!$E$2:$E$73,MATCH($A9,'Team Ratings'!$A$2:$A$73,0)),"")} -> 133.3 | H9: {=IFERROR(INDEX('Team Ratings'!$F$2:$F$73,MATCH($A9,'Team Ratings'!$A$2:$A$73,0)),"")} -> 100.3 | I9: {=IFERROR(INDEX('Team Ratings'!$G$2:$G$73,MATCH($A9,'Team Ratings'!$A$2:$A$73,0)),"")} -> 33 | J9: {=IFERROR(INDEX('Team Ratings'!$H$2:$H$73,MATCH($A9,'Team Ratings'!$A$2:$A$73,0)),"")} -> 57.6 | K9: {=IFERROR(INDEX('Team Ratings'!$I$2:$I$73,MATCH($A9,'Team Ratings'!$A$2:$A$73,0)),"")} -> 52.3 | L9: {=IFERROR(INDEX('Team Ratings'!$J$2:$J$73,MATCH($A9,'Team Ratings'!$A$2:$A$73,0)),"")} -> 13.5 | M9: {=IFERROR(INDEX('Team Ratings'!$K$2:$K$73,MATCH($A9,'Team Ratings'!$A$2:$A$73,0)),"")} -> 15.6 | N9: {=IFERROR(INDEX('Team Ratings'!$L$2:$L$73,MATCH($A9,'Team Ratings'!$A$2:$A$73,0)),"")} -> 36.3 | O9: {=IFERROR(INDEX('Team Ratings'!$M$2:$M$73,MATCH($A9,'Team Ratings'!$A$2:$A$73,0)),"")} -> 26.4 | P9: {=IFERROR(INDEX('Team Ratings'!$N$2:$N$73,MATCH($A9,'Team Ratings'!$A$2:$A$73,0)),"")} -> 28.6 | Q9: {=IFERROR(INDEX('Team Ratings'!$O$2:$O$73,MATCH($A9,'Team Ratings'!$A$2:$A$73,0)),"")} -> 37.9 | R9: {=IFERROR(INDEX('Team Ratings'!$P$2:$P$73,MATCH($A9,'Team Ratings'!$A$2:$A$73,0)),"")} -> 34.2 | S9: {=IFERROR(INDEX('Team Ratings'!$Q$2:$Q$73,MATCH($A9,'Team Ratings'!$A$2:$A$73,0)),0)} -> 0 | T9: {=IFERROR(INDEX('Team Ratings'!$R$2:$R$73,MATCH($A9,'Team Ratings'!$A$2:$A$73,0)),"")} -> 140.5 | U9: {=IFERROR(INDEX('Team Ratings'!$S$2:$S$73,MATCH($A9,'Team Ratings'!$A$2:$A$73,0)),"")} -> 105.3 | V9: =IF(OR(T9="",U9=""),"",T9-U9) -> 35.2 | W9: =IF(OR(V9="",I9=""),"",V9-I9) -> 2.2 | X9: =IF(OR(I9="",V9=""),"",ROUND((I9*0.75)+(V9*0.25),3)) -> 33.55 | Y9: =IFERROR(ROUND(Q9-INDEX($R$2:$R$65,MATCH($D9,$A$2:$A$65,0)),3),"") -> 2.1 | Z9: =IFERROR(ROUND(M9-INDEX($L$2:$L$65,MATCH($D9,$A$2:$A$65,0)),3),"") -> 0.8 | AA9: =IFERROR(ROUND(MAX(0,MIN(10,5+((N9-INDEX($O$2:$O$65,MATCH($D9,$A$2:$A$65,0)))+(O9-INDEX($N$2:$N$65,MATCH($D9,$A$2:$A$65,0))))/2)),3),"") -> 4.65 | AB9: =IFERROR(ROUND((1/B9)*4 + (V9/MAX($V$2:$V$65))*4 + (1-(L9/MAX($L$2:$L$65)))*2 + (P9/MAX($P$2:$P$65)) + (O9/MAX($O$2:$O$65)),2),"") -> 7.57 | AC9: =ROUND((0.35*IFERROR((X9-AVERAGE($X$2:$X$65))/_xlfn.STDEV.P($X$2:$X$65),0)) + (0.2*IFERROR((W9-AVERAGE($W$2:$W$65))/_xlfn.STDEV.P($W$2:$W$65),0)) + (0.15*IFERROR((Y9-AVERAGE($Y$2:$Y$65))/_xlfn.STDEV.P($Y$2:$Y$65),0)) + (0.1*IFERROR((Z9-AVERAGE($Z$2:$Z$65))/_xlfn.STDEV.P($Z$2:$Z$65),0)) + (0.1*IFERROR((AA9-AVERAGE($AA$2:$AA$65))/_xlfn.STDEV.P($AA$2:$AA$65),0)) + (0.05*IFERROR((AB9-AVERAGE($AB$2:$AB$65))/_xlfn.STDEV.P($AB$2:$AB$65),0)) + (0.05*IFERROR((S9-AVERAGE($S$2:$S$65))/IF(_xlfn.STDEV.P($S$2:$S$65)=0,1,_xlfn.STDEV.P($S$2:$S$65)),0)),4) -> 0.5421 | AD9: =IF(OR($A9="",$D9=""),"",IF($A9<=$D9,$A9&"|"&$D9,$D9&"|"&$A9)) -> Purdue|Queens | AE9: G16 | AF9: G40 | AG9: Team 2 | AH9: =AND($A9<>"",$D9<>"",ISNUMBER($AC9)) -> TRUE | AI9: {=IFERROR(INDEX(Matchups!$N$2:$N$64,MATCH($AE9,Matchups!$A$2:$A$64,0)),"")} -> Purdue | AJ9: {=IFERROR(INDEX(Matchups!$O$2:$O$64,MATCH($AE9,Matchups!$A$2:$A$64,0)),"")} -> 61.2 | AK9: {=IFERROR(INDEX(Matchups!$T$2:$T$64,MATCH($AE9,Matchups!$A$2:$A$64,0)),"")} -> ΔComposite=0.94; AdjNET Δ=-33.3; 3PT Δ=-0.4; TO Δ=0.7; REB Δ=0.7 | AL9: {=IFERROR(INDEX(Matchups!$P$2:$P$64,MATCH($AE9,Matchups!$A$2:$A$64,0)),"")} | AM9: =IF($AI9="","",IF($A9=$AI9,"Yes","No")) -> Yes | AN9: =IF($AM9="Yes",$AF9,"") -> G40 | AO9: =IF($AM9="Yes",$AG9,"") -> Team 2
A10: Michigan St. | B10: {=IFERROR(INDEX('Team Ratings'!$B$2:$B$73,MATCH($A10,'Team Ratings'!$A$2:$A$73,0)),"")} -> 3 | C10: {=IFERROR(INDEX('Team Ratings'!$C$2:$C$73,MATCH($A10,'Team Ratings'!$A$2:$A$73,0)),"")} -> East | D10: North Dakota St. | E10: {=IFERROR(INDEX('Team Ratings'!$B$2:$B$73,MATCH($D10,'Team Ratings'!$A$2:$A$73,0)),"")} -> 14 | F10: {=IFERROR(INDEX('Team Ratings'!$D$2:$D$73,MATCH($A10,'Team Ratings'!$A$2:$A$73,0)),"")} -> 0.9438 | G10: {=IFERROR(INDEX('Team Ratings'!$E$2:$E$73,MATCH($A10,'Team Ratings'!$A$2:$A$73,0)),"")} -> 122.9 | H10: {=IFERROR(INDEX('Team Ratings'!$F$2:$F$73,MATCH($A10,'Team Ratings'!$A$2:$A$73,0)),"")} -> 96.2 | I10: {=IFERROR(INDEX('Team Ratings'!$G$2:$G$73,MATCH($A10,'Team Ratings'!$A$2:$A$73,0)),"")} -> 26.7 | J10: {=IFERROR(INDEX('Team Ratings'!$H$2:$H$73,MATCH($A10,'Team Ratings'!$A$2:$A$73,0)),"")} -> 53.6 | K10: {=IFERROR(INDEX('Team Ratings'!$I$2:$I$73,MATCH($A10,'Team Ratings'!$A$2:$A$73,0)),"")} -> 48.6 | L10: {=IFERROR(INDEX('Team Ratings'!$J$2:$J$73,MATCH($A10,'Team Ratings'!$A$2:$A$73,0)),"")} -> 17.1 | M10: {=IFERROR(INDEX('Team Ratings'!$K$2:$K$73,MATCH($A10,'Team Ratings'!$A$2:$A$73,0)),"")} -> 14.8 | N10: {=IFERROR(INDEX('Team Ratings'!$L$2:$L$73,MATCH($A10,'Team Ratings'!$A$2:$A$73,0)),"")} -> 38.5 | O10: {=IFERROR(INDEX('Team Ratings'!$M$2:$M$73,MATCH($A10,'Team Ratings'!$A$2:$A$73,0)),"")} -> 22.6 | P10: {=IFERROR(INDEX('Team Ratings'!$N$2:$N$73,MATCH($A10,'Team Ratings'!$A$2:$A$73,0)),"")} -> 36.2 | Q10: {=IFERROR(INDEX('Team Ratings'!$O$2:$O$73,MATCH($A10,'Team Ratings'!$A$2:$A$73,0)),"")} -> 35.9 | R10: {=IFERROR(INDEX('Team Ratings'!$P$2:$P$73,MATCH($A10,'Team Ratings'!$A$2:$A$73,0)),"")} -> 32.9 | S10: {=IFERROR(INDEX('Team Ratings'!$Q$2:$Q$73,MATCH($A10,'Team Ratings'!$A$2:$A$73,0)),0)} -> 0 | T10: {=IFERROR(INDEX('Team Ratings'!$R$2:$R$73,MATCH($A10,'Team Ratings'!$A$2:$A$73,0)),"")} -> 135 | U10: {=IFERROR(INDEX('Team Ratings'!$S$2:$S$73,MATCH($A10,'Team Ratings'!$A$2:$A$73,0)),"")} -> 108.6 | V10: =IF(OR(T10="",U10=""),"",T10-U10) -> 26.4 | W10: =IF(OR(V10="",I10=""),"",V10-I10) -> -0.3 | X10: =IF(OR(I10="",V10=""),"",ROUND((I10*0.75)+(V10*0.25),3)) -> 26.625 | Y10: =IFERROR(ROUND(Q10-INDEX($R$2:$R$65,MATCH($D10,$A$2:$A$65,0)),3),"") -> 2.4 | Z10: =IFERROR(ROUND(M10-INDEX($L$2:$L$65,MATCH($D10,$A$2:$A$65,0)),3),"") -> -0.8 | AA10: =IFERROR(ROUND(MAX(0,MIN(10,5+((N10-INDEX($O$2:$O$65,MATCH($D10,$A$2:$A$65,0)))+(O10-INDEX($N$2:$N$65,MATCH($D10,$A$2:$A$65,0))))/2)),3),"") -> 5.9 | AB10: =IFERROR(ROUND((1/B10)*4 + (V10/MAX($V$2:$V$65))*4 + (1-(L10/MAX($L$2:$L$65)))*2 + (P10/MAX($P$2:$P$65)) + (O10/MAX($O$2:$O$65)),2),"") -> 5.7 | AC10: =ROUND((0.35*IFERROR((X10-AVERAGE($X$2:$X$65))/_xlfn.STDEV.P($X$2:$X$65),0)) + (0.2*IFERROR((W10-AVERAGE($W$2:$W$65))/_xlfn.STDEV.P($W$2:$W$65),0)) + (0.15*IFERROR((Y10-AVERAGE($Y$2:$Y$65))/_xlfn.STDEV.P($Y$2:$Y$65),0)) + (0.1*IFERROR((Z10-AVERAGE($Z$2:$Z$65))/_xlfn.STDEV.P($Z$2:$Z$65),0)) + (0.1*IFERROR((AA10-AVERAGE($AA$2:$AA$65))/_xlfn.STDEV.P($AA$2:$AA$65),0)) + (0.05*IFERROR((AB10-AVERAGE($AB$2:$AB$65))/_xlfn.STDEV.P($AB$2:$AB$65),0)) + (0.05*IFERROR((S10-AVERAGE($S$2:$S$65))/IF(_xlfn.STDEV.P($S$2:$S$65)=0,1,_xlfn.STDEV.P($S$2:$S$65)),0)),4) -> 0.2239 | AD10: =IF(OR($A10="",$D10=""),"",IF($A10<=$D10,$A10&"|"&$D10,$D10&"|"&$A10)) -> Michigan St.|North Dakota St. | AE10: G6 | AF10: G35 | AG10: Team 2 | AH10: =AND($A10<>"",$D10<>"",ISNUMBER($AC10)) -> TRUE | AI10: {=IFERROR(INDEX(Matchups!$N$2:$N$64,MATCH($AE10,Matchups!$A$2:$A$64,0)),"")} -> Michigan St. | AJ10: {=IFERROR(INDEX(Matchups!$O$2:$O$64,MATCH($AE10,Matchups!$A$2:$A$64,0)),"")} -> 55.2 | AK10: {=IFERROR(INDEX(Matchups!$T$2:$T$64,MATCH($AE10,Matchups!$A$2:$A$64,0)),"")} -> ΔComposite=0.43; AdjNET Δ=-19.3; 3PT Δ=0.4; TO Δ=2.4; REB Δ=-1.8 | AL10: {=IFERROR(INDEX(Matchups!$P$2:$P$64,MATCH($AE10,Matchups!$A$2:$A$64,0)),"")} | AM10: =IF($AI10="","",IF($A10=$AI10,"Yes","No")) -> Yes | AN10: =IF($AM10="Yes",$AF10,"") -> G35 | AO10: =IF($AM10="Yes",$AG10,"") -> Team 2
A11: Virginia | B11: {=IFERROR(INDEX('Team Ratings'!$B$2:$B$73,MATCH($A11,'Team Ratings'!$A$2:$A$73,0)),"")} -> 3 | C11: {=IFERROR(INDEX('Team Ratings'!$C$2:$C$73,MATCH($A11,'Team Ratings'!$A$2:$A$73,0)),"")} -> Midwest | D11: Wright St. | E11: {=IFERROR(INDEX('Team Ratings'!$B$2:$B$73,MATCH($D11,'Team Ratings'!$A$2:$A$73,0)),"")} -> 14 | F11: {=IFERROR(INDEX('Team Ratings'!$D$2:$D$73,MATCH($A11,'Team Ratings'!$A$2:$A$73,0)),"")} -> 0.9427 | G11: {=IFERROR(INDEX('Team Ratings'!$E$2:$E$73,MATCH($A11,'Team Ratings'!$A$2:$A$73,0)),"")} -> 122.3 | H11: {=IFERROR(INDEX('Team Ratings'!$F$2:$F$73,MATCH($A11,'Team Ratings'!$A$2:$A$73,0)),"")} -> 95.8 | I11: {=IFERROR(INDEX('Team Ratings'!$G$2:$G$73,MATCH($A11,'Team Ratings'!$A$2:$A$73,0)),"")} -> 26.5 | J11: {=IFERROR(INDEX('Team Ratings'!$H$2:$H$73,MATCH($A11,'Team Ratings'!$A$2:$A$73,0)),"")} -> 54.6 | K11: {=IFERROR(INDEX('Team Ratings'!$I$2:$I$73,MATCH($A11,'Team Ratings'!$A$2:$A$73,0)),"")} -> 45.3 | L11: {=IFERROR(INDEX('Team Ratings'!$J$2:$J$73,MATCH($A11,'Team Ratings'!$A$2:$A$73,0)),"")} -> 16 | M11: {=IFERROR(INDEX('Team Ratings'!$K$2:$K$73,MATCH($A11,'Team Ratings'!$A$2:$A$73,0)),"")} -> 15.6 | N11: {=IFERROR(INDEX('Team Ratings'!$L$2:$L$73,MATCH($A11,'Team Ratings'!$A$2:$A$73,0)),"")} -> 37.9 | O11: {=IFERROR(INDEX('Team Ratings'!$M$2:$M$73,MATCH($A11,'Team Ratings'!$A$2:$A$73,0)),"")} -> 29.2 | P11: {=IFERROR(INDEX('Team Ratings'!$N$2:$N$73,MATCH($A11,'Team Ratings'!$A$2:$A$73,0)),"")} -> 33 | Q11: {=IFERROR(INDEX('Team Ratings'!$O$2:$O$73,MATCH($A11,'Team Ratings'!$A$2:$A$73,0)),"")} -> 35.9 | R11: {=IFERROR(INDEX('Team Ratings'!$P$2:$P$73,MATCH($A11,'Team Ratings'!$A$2:$A$73,0)),"")} -> 30.9 | S11: {=IFERROR(INDEX('Team Ratings'!$Q$2:$Q$73,MATCH($A11,'Team Ratings'!$A$2:$A$73,0)),0)} -> 0 | T11: {=IFERROR(INDEX('Team Ratings'!$R$2:$R$73,MATCH($A11,'Team Ratings'!$A$2:$A$73,0)),"")} -> 126.7 | U11: {=IFERROR(INDEX('Team Ratings'!$S$2:$S$73,MATCH($A11,'Team Ratings'!$A$2:$A$73,0)),"")} -> 96 | V11: =IF(OR(T11="",U11=""),"",T11-U11) -> 30.7 | W11: =IF(OR(V11="",I11=""),"",V11-I11) -> 4.2 | X11: =IF(OR(I11="",V11=""),"",ROUND((I11*0.75)+(V11*0.25),3)) -> 27.55 | Y11: =IFERROR(ROUND(Q11-INDEX($R$2:$R$65,MATCH($D11,$A$2:$A$65,0)),3),"") -> 2.3 | Z11: =IFERROR(ROUND(M11-INDEX($L$2:$L$65,MATCH($D11,$A$2:$A$65,0)),3),"") -> -0.7 | AA11: =IFERROR(ROUND(MAX(0,MIN(10,5+((N11-INDEX($O$2:$O$65,MATCH($D11,$A$2:$A$65,0)))+(O11-INDEX($N$2:$N$65,MATCH($D11,$A$2:$A$65,0))))/2)),3),"") -> 7.35 | AB11: =IFERROR(ROUND((1/B11)*4 + (V11/MAX($V$2:$V$65))*4 + (1-(L11/MAX($L$2:$L$65)))*2 + (P11/MAX($P$2:$P$65)) + (O11/MAX($O$2:$O$65)),2),"") -> 6.37 | AC11: =ROUND((0.35*IFERROR((X11-AVERAGE($X$2:$X$65))/_xlfn.STDEV.P($X$2:$X$65),0)) + (0.2*IFERROR((W11-AVERAGE($W$2:$W$65))/_xlfn.STDEV.P($W$2:$W$65),0)) + (0.15*IFERROR((Y11-AVERAGE($Y$2:$Y$65))/_xlfn.STDEV.P($Y$2:$Y$65),0)) + (0.1*IFERROR((Z11-AVERAGE($Z$2:$Z$65))/_xlfn.STDEV.P($Z$2:$Z$65),0)) + (0.1*IFERROR((AA11-AVERAGE($AA$2:$AA$65))/_xlfn.STDEV.P($AA$2:$AA$65),0)) + (0.05*IFERROR((AB11-AVERAGE($AB$2:$AB$65))/_xlfn.STDEV.P($AB$2:$AB$65),0)) + (0.05*IFERROR((S11-AVERAGE($S$2:$S$65))/IF(_xlfn.STDEV.P($S$2:$S$65)=0,1,_xlfn.STDEV.P($S$2:$S$65)),0)),4) -> 0.4241 | AD11: =IF(OR($A11="",$D11=""),"",IF($A11<=$D11,$A11&"|"&$D11,$D11&"|"&$A11)) -> Virginia|Wright St. | AE11: G30 | AF11: G47 | AG11: Team 2 | AH11: =AND($A11<>"",$D11<>"",ISNUMBER($AC11)) -> TRUE | AI11: {=IFERROR(INDEX(Matchups!$N$2:$N$64,MATCH($AE11,Matchups!$A$2:$A$64,0)),"")} -> Virginia | AJ11: {=IFERROR(INDEX(Matchups!$O$2:$O$64,MATCH($AE11,Matchups!$A$2:$A$64,0)),"")} -> 59.5 | AK11: {=IFERROR(INDEX(Matchups!$T$2:$T$64,MATCH($AE11,Matchups!$A$2:$A$64,0)),"")} -> ΔComposite=0.79; AdjNET Δ=23.4; 3PT Δ=-2.9; TO Δ=-1.2; REB Δ=4.7 | AL11: {=IFERROR(INDEX(Matchups!$P$2:$P$64,MATCH($AE11,Matchups!$A$2:$A$64,0)),"")} | AM11: =IF($AI11="","",IF($A11=$AI11,"Yes","No")) -> Yes | AN11: =IF($AM11="Yes",$AF11,"") -> G47 | AO11: =IF($AM11="Yes",$AG11,"") -> Team 2
A12: Illinois | B12: {=IFERROR(INDEX('Team Ratings'!$B$2:$B$73,MATCH($A12,'Team Ratings'!$A$2:$A$73,0)),"")} -> 3 | C12: {=IFERROR(INDEX('Team Ratings'!$C$2:$C$73,MATCH($A12,'Team Ratings'!$A$2:$A$73,0)),"")} -> South | D12: Penn | E12: {=IFERROR(INDEX('Team Ratings'!$B$2:$B$73,MATCH($D12,'Team Ratings'!$A$2:$A$73,0)),"")} -> 14 | F12: {=IFERROR(INDEX('Team Ratings'!$D$2:$D$73,MATCH($A12,'Team Ratings'!$A$2:$A$73,0)),"")} -> 0.9676 | G12: {=IFERROR(INDEX('Team Ratings'!$E$2:$E$73,MATCH($A12,'Team Ratings'!$A$2:$A$73,0)),"")} -> 131.9 | H12: {=IFERROR(INDEX('Team Ratings'!$F$2:$F$73,MATCH($A12,'Team Ratings'!$A$2:$A$73,0)),"")} -> 98.2 | I12: {=IFERROR(INDEX('Team Ratings'!$G$2:$G$73,MATCH($A12,'Team Ratings'!$A$2:$A$73,0)),"")} -> 33.7 | J12: {=IFERROR(INDEX('Team Ratings'!$H$2:$H$73,MATCH($A12,'Team Ratings'!$A$2:$A$73,0)),"")} -> 55.1 | K12: {=IFERROR(INDEX('Team Ratings'!$I$2:$I$73,MATCH($A12,'Team Ratings'!$A$2:$A$73,0)),"")} -> 47.6 | L12: {=IFERROR(INDEX('Team Ratings'!$J$2:$J$73,MATCH($A12,'Team Ratings'!$A$2:$A$73,0)),"")} -> 13.2 | M12: {=IFERROR(INDEX('Team Ratings'!$K$2:$K$73,MATCH($A12,'Team Ratings'!$A$2:$A$73,0)),"")} -> 11.6 | N12: {=IFERROR(INDEX('Team Ratings'!$L$2:$L$73,MATCH($A12,'Team Ratings'!$A$2:$A$73,0)),"")} -> 38.7 | O12: {=IFERROR(INDEX('Team Ratings'!$M$2:$M$73,MATCH($A12,'Team Ratings'!$A$2:$A$73,0)),"")} -> 27 | P12: {=IFERROR(INDEX('Team Ratings'!$N$2:$N$73,MATCH($A12,'Team Ratings'!$A$2:$A$73,0)),"")} -> 32.9 | Q12: {=IFERROR(INDEX('Team Ratings'!$O$2:$O$73,MATCH($A12,'Team Ratings'!$A$2:$A$73,0)),"")} -> 34.7 | R12: {=IFERROR(INDEX('Team Ratings'!$P$2:$P$73,MATCH($A12,'Team Ratings'!$A$2:$A$73,0)),"")} -> 31.4 | S12: {=IFERROR(INDEX('Team Ratings'!$Q$2:$Q$73,MATCH($A12,'Team Ratings'!$A$2:$A$73,0)),0)} -> 0 | T12: {=IFERROR(INDEX('Team Ratings'!$R$2:$R$73,MATCH($A12,'Team Ratings'!$A$2:$A$73,0)),"")} -> 126.1 | U12: {=IFERROR(INDEX('Team Ratings'!$S$2:$S$73,MATCH($A12,'Team Ratings'!$A$2:$A$73,0)),"")} -> 98.9 | V12: =IF(OR(T12="",U12=""),"",T12-U12) -> 27.2 | W12: =IF(OR(V12="",I12=""),"",V12-I12) -> -6.5 | X12: =IF(OR(I12="",V12=""),"",ROUND((I12*0.75)+(V12*0.25),3)) -> 32.075 | Y12: =IFERROR(ROUND(Q12-INDEX($R$2:$R$65,MATCH($D12,$A$2:$A$65,0)),3),"") -> 3 | Z12: =IFERROR(ROUND(M12-INDEX($L$2:$L$65,MATCH($D12,$A$2:$A$65,0)),3),"") -> -3.8 | AA12: =IFERROR(ROUND(MAX(0,MIN(10,5+((N12-INDEX($O$2:$O$65,MATCH($D12,$A$2:$A$65,0)))+(O12-INDEX($N$2:$N$65,MATCH($D12,$A$2:$A$65,0))))/2)),3),"") -> 7.45 | AB12: =IFERROR(ROUND((1/B12)*4 + (V12/MAX($V$2:$V$65))*4 + (1-(L12/MAX($L$2:$L$65)))*2 + (P12/MAX($P$2:$P$65)) + (O12/MAX($O$2:$O$65)),2),"") -> 6.23 | AC12: =ROUND((0.35*IFERROR((X12-AVERAGE($X$2:$X$65))/_xlfn.STDEV.P($X$2:$X$65),0)) + (0.2*IFERROR((W12-AVERAGE($W$2:$W$65))/_xlfn.STDEV.P($W$2:$W$65),0)) + (0.15*IFERROR((Y12-AVERAGE($Y$2:$Y$65))/_xlfn.STDEV.P($Y$2:$Y$65),0)) + (0.1*IFERROR((Z12-AVERAGE($Z$2:$Z$65))/_xlfn.STDEV.P($Z$2:$Z$65),0)) + (0.1*IFERROR((AA12-AVERAGE($AA$2:$AA$65))/_xlfn.STDEV.P($AA$2:$AA$65),0)) + (0.05*IFERROR((AB12-AVERAGE($AB$2:$AB$65))/_xlfn.STDEV.P($AB$2:$AB$65),0)) + (0.05*IFERROR((S12-AVERAGE($S$2:$S$65))/IF(_xlfn.STDEV.P($S$2:$S$65)=0,1,_xlfn.STDEV.P($S$2:$S$65)),0)),4) -> 0.255 | AD12: =IF(OR($A12="",$D12=""),"",IF($A12<=$D12,$A12&"|"&$D12,$D12&"|"&$A12)) -> Illinois|Penn | AE12: G22 | AF12: G43 | AG12: Team 2 | AH12: =AND($A12<>"",$D12<>"",ISNUMBER($AC12)) -> TRUE | AI12: {=IFERROR(INDEX(Matchups!$N$2:$N$64,MATCH($AE12,Matchups!$A$2:$A$64,0)),"")} -> Illinois | AJ12: {=IFERROR(INDEX(Matchups!$O$2:$O$64,MATCH($AE12,Matchups!$A$2:$A$64,0)),"")} -> 52.2 | AK12: {=IFERROR(INDEX(Matchups!$T$2:$T$64,MATCH($AE12,Matchups!$A$2:$A$64,0)),"")} -> ΔComposite=0.19; AdjNET Δ=28.3; 3PT Δ=-4.3; TO Δ=-8.4; REB Δ=4.9 | AL12: {=IFERROR(INDEX(Matchups!$P$2:$P$64,MATCH($AE12,Matchups!$A$2:$A$64,0)),"")} | AM12: =IF($AI12="","",IF($A12=$AI12,"Yes","No")) -> Yes | AN12: =IF($AM12="Yes",$AF12,"") -> G43 | AO12: =IF($AM12="Yes",$AG12,"") -> Team 2
A13: Gonzaga | B13: {=IFERROR(INDEX('Team Ratings'!$B$2:$B$73,MATCH($A13,'Team Ratings'!$A$2:$A$73,0)),"")} -> 3 | C13: {=IFERROR(INDEX('Team Ratings'!$C$2:$C$73,MATCH($A13,'Team Ratings'!$A$2:$A$73,0)),"")} -> West | D13: Kennesaw St. | E13: {=IFERROR(INDEX('Team Ratings'!$B$2:$B$73,MATCH($D13,'Team Ratings'!$A$2:$A$73,0)),"")} -> 14 | F13: {=IFERROR(INDEX('Team Ratings'!$D$2:$D$73,MATCH($A13,'Team Ratings'!$A$2:$A$73,0)),"")} -> 0.9446 | G13: {=IFERROR(INDEX('Team Ratings'!$E$2:$E$73,MATCH($A13,'Team Ratings'!$A$2:$A$73,0)),"")} -> 120.3 | H13: {=IFERROR(INDEX('Team Ratings'!$F$2:$F$73,MATCH($A13,'Team Ratings'!$A$2:$A$73,0)),"")} -> 94 | I13: {=IFERROR(INDEX('Team Ratings'!$G$2:$G$73,MATCH($A13,'Team Ratings'!$A$2:$A$73,0)),"")} -> 26.3 | J13: {=IFERROR(INDEX('Team Ratings'!$H$2:$H$73,MATCH($A13,'Team Ratings'!$A$2:$A$73,0)),"")} -> 56.3 | K13: {=IFERROR(INDEX('Team Ratings'!$I$2:$I$73,MATCH($A13,'Team Ratings'!$A$2:$A$73,0)),"")} -> 46.2 | L13: {=IFERROR(INDEX('Team Ratings'!$J$2:$J$73,MATCH($A13,'Team Ratings'!$A$2:$A$73,0)),"")} -> 13.7 | M13: {=IFERROR(INDEX('Team Ratings'!$K$2:$K$73,MATCH($A13,'Team Ratings'!$A$2:$A$73,0)),"")} -> 20.5 | N13: {=IFERROR(INDEX('Team Ratings'!$L$2:$L$73,MATCH($A13,'Team Ratings'!$A$2:$A$73,0)),"")} -> 34.8 | O13: {=IFERROR(INDEX('Team Ratings'!$M$2:$M$73,MATCH($A13,'Team Ratings'!$A$2:$A$73,0)),"")} -> 25.9 | P13: {=IFERROR(INDEX('Team Ratings'!$N$2:$N$73,MATCH($A13,'Team Ratings'!$A$2:$A$73,0)),"")} -> 31.1 | Q13: {=IFERROR(INDEX('Team Ratings'!$O$2:$O$73,MATCH($A13,'Team Ratings'!$A$2:$A$73,0)),"")} -> 34 | R13: {=IFERROR(INDEX('Team Ratings'!$P$2:$P$73,MATCH($A13,'Team Ratings'!$A$2:$A$73,0)),"")} -> 30.8 | S13: {=IFERROR(INDEX('Team Ratings'!$Q$2:$Q$73,MATCH($A13,'Team Ratings'!$A$2:$A$73,0)),0)} -> 0 | T13: {=IFERROR(INDEX('Team Ratings'!$R$2:$R$73,MATCH($A13,'Team Ratings'!$A$2:$A$73,0)),"")} -> 119.2 | U13: {=IFERROR(INDEX('Team Ratings'!$S$2:$S$73,MATCH($A13,'Team Ratings'!$A$2:$A$73,0)),"")} -> 93.9 | V13: =IF(OR(T13="",U13=""),"",T13-U13) -> 25.3 | W13: =IF(OR(V13="",I13=""),"",V13-I13) -> -1 | X13: =IF(OR(I13="",V13=""),"",ROUND((I13*0.75)+(V13*0.25),3)) -> 26.05 | Y13: =IFERROR(ROUND(Q13-INDEX($R$2:$R$65,MATCH($D13,$A$2:$A$65,0)),3),"") -> 0.1 | Z13: =IFERROR(ROUND(M13-INDEX($L$2:$L$65,MATCH($D13,$A$2:$A$65,0)),3),"") -> 3.8 | AA13: =IFERROR(ROUND(MAX(0,MIN(10,5+((N13-INDEX($O$2:$O$65,MATCH($D13,$A$2:$A$65,0)))+(O13-INDEX($N$2:$N$65,MATCH($D13,$A$2:$A$65,0))))/2)),3),"") -> 1.95 | AB13: =IFERROR(ROUND((1/B13)*4 + (V13/MAX($V$2:$V$65))*4 + (1-(L13/MAX($L$2:$L$65)))*2 + (P13/MAX($P$2:$P$65)) + (O13/MAX($O$2:$O$65)),2),"") -> 5.92 | AC13: =ROUND((0.35*IFERROR((X13-AVERAGE($X$2:$X$65))/_xlfn.STDEV.P($X$2:$X$65),0)) + (0.2*IFERROR((W13-AVERAGE($W$2:$W$65))/_xlfn.STDEV.P($W$2:$W$65),0)) + (0.15*IFERROR((Y13-AVERAGE($Y$2:$Y$65))/_xlfn.STDEV.P($Y$2:$Y$65),0)) + (0.1*IFERROR((Z13-AVERAGE($Z$2:$Z$65))/_xlfn.STDEV.P($Z$2:$Z$65),0)) + (0.1*IFERROR((AA13-AVERAGE($AA$2:$AA$65))/_xlfn.STDEV.P($AA$2:$AA$65),0)) + (0.05*IFERROR((AB13-AVERAGE($AB$2:$AB$65))/_xlfn.STDEV.P($AB$2:$AB$65),0)) + (0.05*IFERROR((S13-AVERAGE($S$2:$S$65))/IF(_xlfn.STDEV.P($S$2:$S$65)=0,1,_xlfn.STDEV.P($S$2:$S$65)),0)),4) -> 0.067 | AD13: =IF(OR($A13="",$D13=""),"",IF($A13<=$D13,$A13&"|"&$D13,$D13&"|"&$A13)) -> Gonzaga|Kennesaw St. | AE13: G14 | AF13: G39 | AG13: Team 2 | AH13: =AND($A13<>"",$D13<>"",ISNUMBER($AC13)) -> TRUE | AI13: {=IFERROR(INDEX(Matchups!$N$2:$N$64,MATCH($AE13,Matchups!$A$2:$A$64,0)),"")} -> Gonzaga | AJ13: {=IFERROR(INDEX(Matchups!$O$2:$O$64,MATCH($AE13,Matchups!$A$2:$A$64,0)),"")} -> 55.5 | AK13: {=IFERROR(INDEX(Matchups!$T$2:$T$64,MATCH($AE13,Matchups!$A$2:$A$64,0)),"")} -> ΔComposite=0.46; AdjNET Δ=-24.5; 3PT Δ=2.8; TO Δ=-1.4; REB Δ=6.1 | AL13: {=IFERROR(INDEX(Matchups!$P$2:$P$64,MATCH($AE13,Matchups!$A$2:$A$64,0)),"")} | AM13: =IF($AI13="","",IF($A13=$AI13,"Yes","No")) -> Yes | AN13: =IF($AM13="Yes",$AF13,"") -> G39 | AO13: =IF($AM13="Yes",$AG13,"") -> Team 2
